Workbook

Sheet Léeme
A1: Métodos de valuación en el tiempo
A2: Emisores: NNN, O, WPC · datos al 28-09-2026 · generado el 13-10-2026
A3: Azul sobre amarillo: insumo, editable. Negro: fórmula o valor calculado por el estudio. Herramienta de análisis, no asesoría de inversión.
A5: Umbrales de la señal (percentil contra la historia propia)
A6: Barato desde el percentil | B6: 0.7
A7: Caro abajo del percentil | B7: 0.3
A9: Supuestos de los modelos de valor (hojas «… valor»)
A10: Prima de riesgo sobre el Treasury | B10: 0.03
A11: Crecimiento del dividendo: mínimo | B11: 0
A12: Crecimiento del dividendo: máximo | B12: 0.04
A13: Crecimiento del flujo, 5 años: mínimo | B13: 0
A14: Crecimiento del flujo, 5 años: máximo | B14: 0.08
A15: Crecimiento perpetuo después | B15: 0.02
A16: r − g mínimo | B16: 0.02
A17: Crecimiento entregado: mínimo | B17: -0.05
A18: Crecimiento entregado: máximo | B18: 0.1
A19: Margen de la señal absoluta de valor | B19: 0.15
A20: Margen de la señal absoluta de crecimiento | B20: 0.01
A22: Los métodos
A23: Múltiplo P/FFO | B23: Precio ÷ flujo por acción conocido (FFO de Nareit; AFFO en WPC). Barato = múltiplo bajo contra su propia historia.
A24: Prima sobre el Treasury | B24: Yield de flujo menos el Treasury a 10 años. Es la Puerta 2 del semáforo.
A25: Prima sobre la tasa real | B25: Yield de flujo menos la tasa real: Treasury a 10 años menos la inflación de 12 meses. El flujo de un REIT crece con la inflación; compararlo contra una tasa nominal castiga los años de inflación alta.
A26: Prima sobre bonos Baa | B26: Yield de flujo menos el rendimiento de los bonos corporativos Baa (Moody's): contra la alternativa de crédito, no contra la libre de riesgo.
A27: Yield de dividendo | B27: Dividendo regular vigente anualizado ÷ precio, contra su propia historia.
A28: Dividendo sobre el Treasury | B28: Yield de dividendo menos el Treasury a 10 años: la lente «contra el bono» del estudio.
A29: Múltiplo contra sus últimos 5 años | B29: Yield de flujo entre su mediana de los cinco años previos. No compara contra toda la historia sino contra el régimen reciente de tasas.
A30: Consenso de los siete | B30: El promedio de los percentiles de los siete métodos (con al menos cuatro disponibles). Es la regla que se recomienda: no se escoge el método que mejor salió, porque con 21 intentos el mejor siempre sale bien por azar.
A31: DDM (Gordon sobre el dividendo) | B31: Dividendo vigente × (1 + g) ÷ (r − g); g = crecimiento del dividendo de los 5 años previos, entre 0% y 4%; r = Treasury a 10 años + 3%. La señal es valor ÷ precio − 1.
A32: DCF del flujo en dos etapas | B32: AFFO por acción (FFO donde no hay) creciendo 5 años a su ritmo de los 5 previos (0% a 8%) y después 2% perpetuo, descontado a r. La señal es valor ÷ precio − 1.
A33: Crecimiento entregado contra implícito | B33: El crecimiento del flujo por acción de los 5 años previos menos el crecimiento perpetuo que justifica el precio con r. Positivo: el mercado descuenta menos de lo que el emisor ha hecho.
A34: NAV aproximado | B34: NOI anualizado del último trimestre ÷ el cap rate de las compras del propio emisor, menos deuda neta y preferentes, por acción. La señal es NAV ÷ precio − 1.
A36: Cómo se calculó
A37: • | B37: Point-in-time (P1): el flujo por acción es el de los últimos 12 meses conocido a cada fecha, con la fecha real de publicación de cada cifra; el Treasury y los bonos Baa, el dato del día hábil anterior; el CPI de un mes, 45 días después de su fecha, que es cuando se publica.
A38: • | B38: Percentil expandible (P5): cada fin de mes contra todos los fines de mes anteriores del mismo emisor, con al menos 36. Nunca contra otro emisor (P4): un yield de 7% puede ser caro en uno y barato en otro.
A39: • | B39: Retornos siguientes: retorno total en dólares con el dividendo neto del 20% de impuesto, anualizado. La alternativa de esperar es el T-bill a 3 meses de esos mismos años, neto del 20%.
A40: • | B40: La evaluación usa fines de trimestre para no contar tres veces casi el mismo mes. Aun así las ventanas de 5 años se enciman: las independientes son una por cada 20 trimestres.
A41: • | B41: Backtest por emisor: la regla de «solo compras, reinversión en 12 meses» del estudio de reglas, con el percentil del método en lugar de la prima del semáforo y sin las puertas de calidad ni de deterioro: barato compra todo y la reserva, medio la mitad, caro nada; nunca vende.
A42: • | B42: Asignación entre emisores: desde el primer mes en que los tres tienen percentil del método; la decisión de fin de mes se ejecuta al cierre de la sesión siguiente; 0.25% de comisión, 20% al dividendo y 10% a la ganancia al vender todo al final. El benchmark reparte en tercios y cada emisor reinvierte sus propios dividendos (P6 llevado a tres papeles).
A43: • | B43: Controles: el espejo (todo al más caro) y cada mitad del periodo por separado, con su propia TIR, se fijaron antes de ver el resultado. El azar se endureció después: la primera versión sorteaba el emisor cada mes, reparte sola el dinero entre los tres y cualquier método le ganaba; la que queda conserva las rachas del método (200 sorteos, semilla fija, reproducible).
A44: • | B44: Pruebas múltiples: siete métodos en tres emisores son 21 intentos. Por eso se recomienda el consenso y no el mejor, y por eso se exige que el resultado aparezca en los tres emisores y en las dos mitades. El consenso se definió después de ver los siete: no escoge por resultado, pero tampoco es una prueba a ciegas.
...

Sheet Hoy
A1: Método | B1: Percentil NNN | C1: Percentil O | D1: Percentil WPC | E1: Señal NNN | F1: Señal O | G1: Señal WPC
A2: Múltiplo P/FFO | B2: 0.63647643 | C2: 0.76760563 | D2: 0.36750789 | E2: =IF(B2="","",IF(B2>='Léeme'!$B$6,"barato",IF(B2<'Léeme'!$B$7,"caro","medio"))) | F2: =IF(C2="","",IF(C2>='Léeme'!$B$6,"barato",IF(C2<'Léeme'!$B$7,"caro","medio"))) | G2: =IF(D2="","",IF(D2>='Léeme'!$B$6,"barato",IF(D2<'Léeme'!$B$7,"caro","medio")))
A3: Prima sobre el Treasury | B3: 0.39826303 | C3: 0.40985915 | D3: 0.011041009 | E3: =IF(B3="","",IF(B3>='Léeme'!$B$6,"barato",IF(B3<'Léeme'!$B$7,"caro","medio"))) | F3: =IF(C3="","",IF(C3>='Léeme'!$B$6,"barato",IF(C3<'Léeme'!$B$7,"caro","medio"))) | G3: =IF(D3="","",IF(D3>='Léeme'!$B$6,"barato",IF(D3<'Léeme'!$B$7,"caro","medio")))
A4: Prima sobre la tasa real | B4: 0.58188586 | C4: 0.6915493 | D4: 0.14984227 | E4: =IF(B4="","",IF(B4>='Léeme'!$B$6,"barato",IF(B4<'Léeme'!$B$7,"caro","medio"))) | F4: =IF(C4="","",IF(C4>='Léeme'!$B$6,"barato",IF(C4<'Léeme'!$B$7,"caro","medio"))) | G4: =IF(D4="","",IF(D4>='Léeme'!$B$6,"barato",IF(D4<'Léeme'!$B$7,"caro","medio")))
A5: Prima sobre bonos Baa | B5: 0.6439206 | C5: 0.81267606 | D5: 0.093059937 | E5: =IF(B5="","",IF(B5>='Léeme'!$B$6,"barato",IF(B5<'Léeme'!$B$7,"caro","medio"))) | F5: =IF(C5="","",IF(C5>='Léeme'!$B$6,"barato",IF(C5<'Léeme'!$B$7,"caro","medio"))) | G5: =IF(D5="","",IF(D5>='Léeme'!$B$6,"barato",IF(D5<'Léeme'!$B$7,"caro","medio")))
A6: Yield de dividendo | B6: 0.46642686 | C6: 0.57942708 | D6: 0.35714286 | E6: =IF(B6="","",IF(B6>='Léeme'!$B$6,"barato",IF(B6<'Léeme'!$B$7,"caro","medio"))) | F6: =IF(C6="","",IF(C6>='Léeme'!$B$6,"barato",IF(C6<'Léeme'!$B$7,"caro","medio"))) | G6: =IF(D6="","",IF(D6>='Léeme'!$B$6,"barato",IF(D6<'Léeme'!$B$7,"caro","medio")))
A7: Dividendo sobre el Treasury | B7: 0.010791367 | C7: 0.014322917 | D7: 0.0043731778 | E7: =IF(B7="","",IF(B7>='Léeme'!$B$6,"barato",IF(B7<'Léeme'!$B$7,"caro","medio"))) | F7: =IF(C7="","",IF(C7>='Léeme'!$B$6,"barato",IF(C7<'Léeme'!$B$7,"caro","medio"))) | G7: =IF(D7="","",IF(D7>='Léeme'!$B$6,"barato",IF(D7<'Léeme'!$B$7,"caro","medio")))
A8: Múltiplo contra sus últimos 5 años | B8: 0.70435967 | C8: 0.98275862 | D8: 0.73843416 | E8: =IF(B8="","",IF(B8>='Léeme'!$B$6,"barato",IF(B8<'Léeme'!$B$7,"caro","medio"))) | F8: =IF(C8="","",IF(C8>='Léeme'!$B$6,"barato",IF(C8<'Léeme'!$B$7,"caro","medio"))) | G8: =IF(D8="","",IF(D8>='Léeme'!$B$6,"barato",IF(D8<'Léeme'!$B$7,"caro","medio")))
A9: Consenso de los siete | B9: 0.49173197 | C9: 0.60831411 | D9: 0.24591447 | E9: =IF(B9="","",IF(B9>='Léeme'!$B$6,"barato",IF(B9<'Léeme'!$B$7,"caro","medio"))) | F9: =IF(C9="","",IF(C9>='Léeme'!$B$6,"barato",IF(C9<'Léeme'!$B$7,"caro","medio"))) | G9: =IF(D9="","",IF(D9>='Léeme'!$B$6,"barato",IF(D9<'Léeme'!$B$7,"caro","medio")))

Sheet Asignación
A1: A cuál de los tres va la aportación del mes: al de percentil más alto contra su propia historia
A3: Método | B3: Desde | C3: TIR | D3: TIR partes iguales | E3: Ventaja | F3: Ventaja al más caro | G3: Ventaja 1ª mitad | H3: Ventaja 2ª mitad | I3: Azar que la iguala | J3: Cambios de emisor | K3: Hoy va a
A4: Múltiplo P/FFO | B4: 37742 | C4: 0.08512453 | D4: 0.078219663 | E4: 69 | F4: -59 | G4: 177 | H4: 88 | I4: 0 | J4: 46 | K4: O
A5: Prima sobre el Treasury | B5: 37742 | C5: 0.0834971 | D5: 0.078219663 | E5: 53 | F5: -34 | G5: 145 | H5: 62 | I5: 0.005 | J5: 51 | K5: O
A6: Prima sobre la tasa real | B6: 37742 | C6: 0.082734053 | D6: 0.078219663 | E6: 45 | F6: -52 | G6: 129 | H6: 39 | I6: 0.005 | J6: 41 | K6: O
A7: Prima sobre bonos Baa | B7: 37742 | C7: 0.084722222 | D7: 0.078219663 | E7: 65 | F7: -44 | G7: 190 | H7: 63 | I7: 0 | J7: 40 | K7: O
A8: Yield de dividendo | B8: 36951 | C8: 0.088748715 | D8: 0.083393574 | E8: 54 | F8: -58 | G8: 178 | H8: 48 | I8: 0.005 | J8: 59 | K8: O
A9: Dividendo sobre el Treasury | B9: 36951 | C9: 0.087675775 | D9: 0.083393574 | E9: 43 | F9: -45 | G9: 96 | H9: 59 | I9: 0.035 | J9: 39 | K9: WPC
A10: Múltiplo contra sus últimos 5 años | B10: 38838 | C10: 0.079293604 | D10: 0.073827403 | E10: 55 | F10: -42 | G10: 117 | H10: 101 | I10: 0.005 | J10: 57 | K10: O
A11: Consenso de los siete | B11: 37742 | C11: 0.085466481 | D11: 0.078219663 | E11: 72 | F11: -53 | G11: 167 | H11: 88 | I11: 0 | J11: 54 | K11: O
A13: Cada fin de trimestre, con el consenso de los siete
A14: Trimestre | B14: NNN | C14: O | D14: WPC | E14: La aportación va a
A15: 1996-T1 | B15: 0.72323794 | E15: =IF(COUNT(B15:D15)<3,"—",INDEX($B$14:$D$14,MATCH(MAX(B15:D15),B15:D15,0)))
A16: 1996-T2 | B16: 0.39166667 | E16: =IF(COUNT(B16:D16)<3,"—",INDEX($B$14:$D$14,MATCH(MAX(B16:D16),B16:D16,0)))
A17: 1996-T3 | B17: 0.5244798 | E17: =IF(COUNT(B17:D17)<3,"—",INDEX($B$14:$D$14,MATCH(MAX(B17:D17),B17:D17,0)))
A18: 1996-T4 | B18: 0.17693237 | E18: =IF(COUNT(B18:D18)<3,"—",INDEX($B$14:$D$14,MATCH(MAX(B18:D18),B18:D18,0)))
A19: 1997-T1 | B19: 0.42139078 | E19: =IF(COUNT(B19:D19)<3,"—",INDEX($B$14:$D$14,MATCH(MAX(B19:D19),B19:D19,0)))
A20: 1997-T2 | B20: 0.33459596 | E20: =IF(COUNT(B20:D20)<3,"—",INDEX($B$14:$D$14,MATCH(MAX(B20:D20),B20:D20,0)))
A21: 1997-T3 | B21: 0.30048309 | E21: =IF(COUNT(B21:D21)<3,"—",INDEX($B$14:$D$14,MATCH(MAX(B21:D21),B21:D21,0)))
A22: 1997-T4 | B22: 0.12188697 | E22: =IF(COUNT(B22:D22)<3,"—",INDEX($B$14:$D$14,MATCH(MAX(B22:D22),B22:D22,0)))
A23: 1998-T1 | B23: 0.24626594 | E23: =IF(COUNT(B23:D23)<3,"—",INDEX($B$14:$D$14,MATCH(MAX(B23:D23),B23:D23,0)))
A24: 1998-T2 | B24: 0.6149172 | E24: =IF(COUNT(B24:D24)<3,"—",INDEX($B$14:$D$14,MATCH(MAX(B24:D24),B24:D24,0)))
A25: 1998-T3 | B25: 0.89453965 | E25: =IF(COUNT(B25:D25)<3,"—",INDEX($B$14:$D$14,MATCH(MAX(B25:D25),B25:D25,0)))
A26: 1998-T4 | B26: 0.95277778 | E26: =IF(COUNT(B26:D26)<3,"—",INDEX($B$14:$D$14,MATCH(MAX(B26:D26),B26:D26,0)))
... A30: 1999-T4 | B30: 0.99347479 | E30: =IF(COUNT(B30:D30)<3,"—",INDEX($B$14:$D$14,MATCH(MAX(B30:D30),B30:D30,0)))
A31: 2000-T1 | B31: 0.98168913 | C31: 0.98846574 | E31: =IF(COUNT(B31:D31)<3,"—",INDEX($B$14:$D$14,MATCH(MAX(B31:D31),B31:D31,0)))
A32: 2000-T2 | B32: 0.96753981 | C32: 0.73737923 | E32: =IF(COUNT(B32:D32)<3,"—",INDEX($B$14:$D$14,MATCH(MAX(B32:D32),B32:D32,0)))
A33: 2000-T3 | B33: 0.98438228 | C33: 0.81503015 | E33: =IF(COUNT(B33:D33)<3,"—",INDEX($B$14:$D$14,MATCH(MAX(B33:D33),B33:D33,0)))
A34: 2000-T4 | B34: 0.97602647 | C34: 0.71043478 | E34: =IF(COUNT(B34:D34)<3,"—",INDEX($B$14:$D$14,MATCH(MAX(B34:D34),B34:D34,0)))
A35: 2001-T1 | B35: 0.78910503 | C35: 0.55926217 | E35: =IF(COUNT(B35:D35)<3,"—",INDEX($B$14:$D$14,MATCH(MAX(B35:D35),B35:D35,0)))
A36: 2001-T2 | B36: 0.56400768 | C36: 0.31604147 | E36: =IF(COUNT(B36:D36)<3,"—",INDEX($B$14:$D$14,MATCH(MAX(B36:D36),B36:D36,0)))
A37: 2001-T3 | B37: 0.67171407 | C37: 0.40743146 | E37: =IF(COUNT(B37:D37)<3,"—",INDEX($B$14:$D$14,MATCH(MAX(B37:D37),B37:D37,0)))
A38: 2001-T4 | B38: 0.65182743 | C38: 0.28639847 | E38: =IF(COUNT(B38:D38)<3,"—",INDEX($B$14:$D$14,MATCH(MAX(B38:D38),B38:D38,0)))
A39: 2002-T1 | B39: 0.50309328 | C39: 0.062416515 | E39: =IF(COUNT(B39:D39)<3,"—",INDEX($B$14:$D$14,MATCH(MAX(B39:D39),B39:D39,0)))
A40: 2002-T2 | B40: 0.33271423 | C40: 0.058775762 | E40: =IF(COUNT(B40:D40)<3,"—",INDEX($B$14:$D$14,MATCH(MAX(B40:D40),B40:D40,0)))
A41: 2002-T3 | B41: 0.43938251 | C41: 0.33771248 | E41: =IF(COUNT(B41:D41)<3,"—",INDEX($B$14:$D$14,MATCH(MAX(B41:D41),B41:D41,0)))
A42: 2002-T4 | B42: 0.53157498 | C42: 0.29386724 | E42: =IF(COUNT(B42:D42)<3,"—",INDEX($B$14:$D$14,MATCH(MAX(B42:D42),B42:D42,0)))
A43: 2003-T1 | B43: 0.57245925 | C43: 0.32728204 | E43: =IF(COUNT(B43:D43)<3,"—",INDEX($B$14:$D$14,MATCH(MAX(B43:D43),B43:D43,0)))
A44: 2003-T2 | B44: 0.37036021 | C44: 0.2454753 | D44: 0.27001096 | E44: =IF(COUNT(B44:D44)<3,"—",INDEX($B$14:$D$14,MATCH(MAX(B44:D44),B44:D44,0)))
A45: 2003-T3 | B45: 0.36979913 | C45: 0.17069567 | D45: 0.096893581 | E45: =IF(COUNT(B45:D45)<3,"—",INDEX($B$14:$D$14,MATCH(MAX(B45:D45),B45:D45,0)))
...

Sheet Evaluación
A1: ¿Predicen? Percentil contra el retorno de los años siguientes, un renglón por trimestre
A3: NNN REIT, Inc. (NNN)
A4: Método | B4: Correlación 1 año | C4: Correlación 5 años | D4: 5 años si barato | E4: 5 años si medio | F4: 5 años si caro | G4: Brecha barato − caro | H4: Caro contra el efectivo | I4: Veces que caro le ganó al efectivo | J4: TIR con el método (solo ese papel) | K4: TIR sin reglas | L4: Ventaja
A5: Múltiplo P/FFO | B5: 0.291 | C5: 0.457 | D5: 0.19329794 | E5: 0.13565686 | F5: 0.08054282 | G5: 0.11275512 | H5: 0.068255118 | I5: 0.84615385 | J5: 0.086491103 | K5: 0.088193309 | L5: -17
A6: Prima sobre el Treasury | B6: 0.293 | C6: 0.529 | D6: 0.17385414 | E6: 0.095283298 | F6: 0.080522553 | G6: 0.093331582 | H6: 0.064925063 | I6: 0.73684211 | J6: 0.087054545 | K6: 0.088193309 | L6: -11
A7: Prima sobre la tasa real | B7: 0.141 | C7: 0.553 | D7: 0.16335406 | E7: 0.097781598 | F7: 0.08054282 | G7: 0.082811244 | H7: 0.052892207 | I7: 0.8 | J7: 0.086941905 | K7: 0.088193309 | L7: -13
A8: Prima sobre bonos Baa | B8: 0.222 | C8: 0.369 | D8: 0.16335406 | E8: 0.085254279 | F8: 0.1002799 | G8: 0.063074166 | H8: 0.09165513 | I8: 0.85714286 | J8: 0.087090746 | K8: 0.088193309 | L8: -11
A9: Yield de dividendo | B9: 0.332 | C9: 0.471 | D9: 0.20539413 | E9: 0.10331107 | F9: 0.088431034 | G9: 0.1169631 | H9: 0.069652062 | I9: 0.86842105 | J9: 0.087386167 | K9: 0.088193309 | L9: -8
A10: Dividendo sobre el Treasury | B10: 0.392 | C10: 0.593 | D10: 0.16069914 | E10: 0.10485413 | F10: 0.055720961 | G10: 0.10497818 | H10: 0.037848204 | I10: 0.73684211 | J10: 0.088142577 | K10: 0.088193309 | L10: -1
A11: Múltiplo contra sus últimos 5 años | B11: 0.126 | C11: 0.19 | D11: 0.16335406 | E11: 0.088094521 | F11: 0.11095707 | G11: 0.05239699 | H11: 0.10322296 | I11: 0.9375 | J11: 0.086056558 | K11: 0.088193309 | L11: -21
A12: Consenso de los siete | B12: 0.299 | C12: 0.534 | D12: 0.20070335 | E12: 0.1123695 | F12: 0.073373941 | G12: 0.12732941 | H12: 0.05665649 | I12: 0.75 | J12: 0.087359293 | K12: 0.088193309 | L12: -8
A15: Realty Income Corporation (O)
A16: Método | B16: Correlación 1 año | C16: Correlación 5 años | D16: 5 años si barato | E16: 5 años si medio | F16: 5 años si caro | G16: Brecha barato − caro | H16: Caro contra el efectivo | I16: Veces que caro le ganó al efectivo | J16: TIR con el método (solo ese papel) | K16: TIR sin reglas | L16: Ventaja
A17: Múltiplo P/FFO | B17: 0.379 | C17: 0.456 | D17: 0.22335445 | E17: 0.16924143 | F17: 0.1024585 | G17: 0.12089595 | H17: 0.092663669 | I17: 0.91304348 | J17: 0.094894533 | K17: 0.098350613 | L17: -35
A18: Prima sobre el Treasury | B18: 0.386 | C18: 0.277 | D18: 0.1765465 | E18: 0.11776756 | F18: 0.10919198 | G18: 0.067354524 | H18: 0.093971742 | I18: 0.86666667 | J18: 0.096684669 | K18: 0.098350613 | L18: -17
A19: Prima sobre la tasa real | B19: 0.057 | C19: 0.296 | D19: 0.1765465 | E19: 0.10362004 | F19: 0.1024585 | G19: 0.074087998 | H19: 0.092663669 | I19: 0.90322581 | J19: 0.095193882 | K19: 0.098350613 | L19: -32
A20: Prima sobre bonos Baa | B20: 0.331 | C20: 0.004 | D20: 0.079839022 | E20: 0.11463509 | F20: 0.11909432 | G20: -0.039255303 | H20: 0.11127447 | I20: 0.95348837 | J20: 0.095736981 | K20: 0.098350613 | L20: -26
A21: Yield de dividendo | B21: 0.26 | C21: 0.608 | D21: 0.22335445 | E21: 0.17156391 | F21: 0.10753134 | G21: 0.11582312 | H21: 0.093971742 | I21: 0.91891892 | J21: 0.095092804 | K21: 0.098350613 | L21: -33
A22: Dividendo sobre el Treasury | B22: 0.344 | C22: 0.45 | D22: 0.18076528 | E22: 0.11313833 | F22: 0.11652919 | G22: 0.06423609 | H22: 0.092663669 | I22: 0.86956522 | J22: 0.097658684 | K22: 0.098350613 | L22: -7
A23: Múltiplo contra sus últimos 5 años | B23: 0.221 | C23: 0.295 | D23: 0.13182595 | E23: 0.1024585 | F23: 0.090192221 | G23: 0.041633731 | H23: 0.068002232 | I23: 0.9 | J23: 0.098158103 | K23: 0.098350613 | L23: -2
A24: Consenso de los siete | B24: 0.372 | C24: 0.363 | D24: 0.1992985 | E24: 0.12887686 | F24: 0.09395317 | G24: 0.10534533 | H24: 0.080651241 | I24: 0.84615385 | J24: 0.096253274 | K24: 0.098350613 | L24: -21
A27: W. P. Carey Inc. (WPC)
A28: Método | B28: Correlación 1 año | C28: Correlación 5 años | D28: 5 años si barato | E28: 5 años si medio | F28: 5 años si caro | G28: Brecha barato − caro | H28: Caro contra el efectivo | I28: Veces que caro le ganó al efectivo | J28: TIR con el método (solo ese papel) | K28: TIR sin reglas | L28: Ventaja
A29: Múltiplo P/FFO | B29: 0.265 | C29: 0.566 | D29: 0.24273252 | E29: 0.15465159 | F29: 0.063224995 | G29: 0.17950752 | H29: 0.05525272 | I29: 0.80851064 | J29: 0.090092894 | K29: 0.093423565 | L29: -33
A30: Prima sobre el Treasury | B30: 0.371 | C30: 0.505 | D30: 0.16289105 | E30: 0.09062331 | F30: 0.048635575 | G30: 0.11425547 | H30: 0.044337829 | I30: 0.64 | J30: 0.092871538 | K30: 0.093423565 | L30: -6
A31: Prima sobre la tasa real | B31: 0.134 | C31: 0.459 | D31: 0.13997026 | E31: 0.099738104 | F31: 0.063224995 | G31: 0.076745262 | H31: 0.05525272 | I31: 0.73913043 | J31: 0.092239918 | K31: 0.093423565 | L31: -12
A32: Prima sobre bonos Baa | B32: 0.355 | C32: 0.481 | D32: 0.12762155 | E32: 0.074800862 | F32: 0.049505848 | G32: 0.078115707 | H32: 0.046014087 | I32: 0.66666667 | J32: 0.094189423 | K32: 0.093423565 | L32: 8
A33: Yield de dividendo | B33: 0.25 | C33: 0.326 | D33: 0.27513493 | E33: 0.10445089 | F33: 0.083385306 | G33: 0.19174963 | H33: 0.067138624 | I33: 0.78571429 | J33: 0.090632689 | K33: 0.093423565 | L33: -28
A34: Dividendo sobre el Treasury | B34: 0.312 | C34: 0.15 | D34: 0.09062331 | E34: 0.099123437 | F34: 0.11837699 | G34: -0.027753682 | H34: 0.096731235 | I34: 0.73684211 | J34: 0.092070981 | K34: 0.093423565 | L34: -14
A35: Múltiplo contra sus últimos 5 años | B35: 0.051 | C35: 0.304 | D35: 0.11132289 | E35: 0.11304145 | F35: 0.07704271 | G35: 0.034280182 | H35: 0.068548684 | I35: 0.80952381 | J35: 0.091881831 | K35: 0.093423565 | L35: -15
A36: Consenso de los siete | B36: 0.375 | C36: 0.525 | D36: 0.24011409 | E36: 0.095746783 | F36: 0.04249346 | G36: 0.19762063 | H36: 0.029337581 | I36: 0.57142857 | J36: 0.092251909 | K36: 0.093423565 | L36: -12

Sheet NNN
A1: Trimestre | B1: Fecha | C1: Precio | D1: Flujo por acción, 12 meses | E1: Dividendo anualizado | F1: Treasury 10 años | G1: Inflación 12 meses | H1: Bonos Baa | I1: Múltiplo precio/flujo | J1: Yield de flujo | K1: Yield de dividendo | L1: Tasa real | M1: Prima sobre el Treasury | N1: Prima sobre la tasa real | O1: Prima sobre bonos Baa | P1: Dividendo sobre el Treasury | Q1: Percentil: Múltiplo P/FFO | R1: Percentil: Prima sobre el Treasury | S1: Percentil: Prima sobre la tasa real | T1: Percentil: Prima sobre bonos Baa | U1: Percentil: Yield de dividendo | V1: Percentil: Dividendo sobre el Treasury | W1: Percentil: Múltiplo contra sus últimos 5 años | X1: Percentil: Consenso de los siete | Y1: Señal del consenso | Z1: Retorno anual, 1 año después | AA1: Retorno anual, 5 años después
A2: 1992-T1 | B2: 33694 | C2: 9.875 | E2: 1.08 | F2: 0.0754 | G2: 0.028189911 | H2: 0.0922 | I2: =IFERROR(C2/D2,"") | J2: =IFERROR(D2/C2,"") | K2: =IFERROR(E2/C2,"") | L2: =IFERROR(F2-G2,"") | M2: =IFERROR(J2-F2,"") | N2: =IFERROR(J2-L2,"") | O2: =IFERROR(J2-H2,"") | P2: =IFERROR(K2-F2,"") | Y2: =IF(X2="","",IF(X2>='Léeme'!$B$6,"barato",IF(X2<'Léeme'!$B$7,"caro","medio"))) | Z2: 0.5178514 | AA2: 0.16304417
A3: 1992-T2 | B3: 33785 | C3: 10 | E3: 1.08 | F3: 0.0714 | G3: 0.030235988 | H3: 0.09 | I3: =IFERROR(C3/D3,"") | J3: =IFERROR(D3/C3,"") | K3: =IFERROR(E3/C3,"") | L3: =IFERROR(F3-G3,"") | M3: =IFERROR(J3-F3,"") | N3: =IFERROR(J3-L3,"") | O3: =IFERROR(J3-H3,"") | P3: =IFERROR(K3-F3,"") | Y3: =IF(X3="","",IF(X3>='Léeme'!$B$6,"barato",IF(X3<'Léeme'!$B$7,"caro","medio"))) | Z3: 0.45112217 | AA3: 0.16773688
A4: 1992-T3 | B4: 33877 | C4: 11.625 | E4: 1.08 | F4: 0.0637 | G4: 0.030746706 | H4: 0.0865 | I4: =IFERROR(C4/D4,"") | J4: =IFERROR(D4/C4,"") | K4: =IFERROR(E4/C4,"") | L4: =IFERROR(F4-G4,"") | M4: =IFERROR(J4-F4,"") | N4: =IFERROR(J4-L4,"") | O4: =IFERROR(J4-H4,"") | P4: =IFERROR(K4-F4,"") | Y4: =IF(X4="","",IF(X4>='Léeme'!$B$6,"barato",IF(X4<'Léeme'!$B$7,"caro","medio"))) | Z4: 0.28902578 | AA4: 0.14100136
A5: 1992-T4 | B5: 33969 | C5: 12.125 | E5: 1.08 | F5: 0.067 | G5: 0.031204644 | H5: 0.0874 | I5: =IFERROR(C5/D5,"") | J5: =IFERROR(D5/C5,"") | K5: =IFERROR(E5/C5,"") | L5: =IFERROR(F5-G5,"") | M5: =IFERROR(J5-F5,"") | N5: =IFERROR(J5-L5,"") | O5: =IFERROR(J5-H5,"") | P5: =IFERROR(K5-F5,"") | Y5: =IF(X5="","",IF(X5>='Léeme'!$B$6,"barato",IF(X5<'Léeme'!$B$7,"caro","medio"))) | Z5: 0.21136269 | AA5: 0.15694074
A6: 1993-T1 | B6: 34059 | C6: 13.875 | D6: 1.15 | E6: 1.08 | F6: 0.0603 | G6: 0.032467532 | H6: 0.082 | I6: =IFERROR(C6/D6,"") | J6: =IFERROR(D6/C6,"") | K6: =IFERROR(E6/C6,"") | L6: =IFERROR(F6-G6,"") | M6: =IFERROR(J6-F6,"") | N6: =IFERROR(J6-L6,"") | O6: =IFERROR(J6-H6,"") | P6: =IFERROR(K6-F6,"") | Y6: =IF(X6="","",IF(X6>='Léeme'!$B$6,"barato",IF(X6<'Léeme'!$B$7,"caro","medio"))) | Z6: 0.066950114 | AA6: 0.12212797
A7: 1993-T2 | B7: 34150 | C7: 13.5 | D7: 1.15 | E7: 1.08 | F7: 0.058 | G7: 0.032211883 | H7: 0.0795 | I7: =IFERROR(C7/D7,"") | J7: =IFERROR(D7/C7,"") | K7: =IFERROR(E7/C7,"") | L7: =IFERROR(F7-G7,"") | M7: =IFERROR(J7-F7,"") | N7: =IFERROR(J7-L7,"") | O7: =IFERROR(J7-H7,"") | P7: =IFERROR(K7-F7,"") | Y7: =IF(X7="","",IF(X7>='Léeme'!$B$6,"barato",IF(X7<'Léeme'!$B$7,"caro","medio"))) | Z7: 0.076982056 | AA7: 0.10907072
A8: 1993-T3 | B8: 34242 | C8: 14 | D8: 1.15 | E8: 1.12 | F8: 0.054 | G8: 0.028409091 | H8: 0.0736 | I8: =IFERROR(C8/D8,"") | J8: =IFERROR(D8/C8,"") | K8: =IFERROR(E8/C8,"") | L8: =IFERROR(F8-G8,"") | M8: =IFERROR(J8-F8,"") | N8: =IFERROR(J8-L8,"") | O8: =IFERROR(J8-H8,"") | P8: =IFERROR(K8-F8,"") | Y8: =IF(X8="","",IF(X8>='Léeme'!$B$6,"barato",IF(X8<'Léeme'!$B$7,"caro","medio"))) | Z8: -0.065884408 | AA8: 0.078706659
A9: 1993-T4 | B9: 34334 | C9: 13.75 | D9: 1.15 | E9: 1.12 | F9: 0.0583 | G9: 0.027445461 | H9: 0.0775 | I9: =IFERROR(C9/D9,"") | J9: =IFERROR(D9/C9,"") | K9: =IFERROR(E9/C9,"") | L9: =IFERROR(F9-G9,"") | M9: =IFERROR(J9-F9,"") | N9: =IFERROR(J9-L9,"") | O9: =IFERROR(J9-H9,"") | P9: =IFERROR(K9-F9,"") | Y9: =IF(X9="","",IF(X9>='Léeme'!$B$6,"barato",IF(X9<'Léeme'!$B$7,"caro","medio"))) | Z9: -0.045724961 | AA9: 0.061587366
A10: 1994-T1 | B10: 34424 | C10: 13.875 | D10: 1.05 | E10: 1.12 | F10: 0.0677 | G10: 0.025157233 | H10: 0.0832 | I10: =IFERROR(C10/D10,"") | J10: =IFERROR(D10/C10,"") | K10: =IFERROR(E10/C10,"") | L10: =IFERROR(F10-G10,"") | M10: =IFERROR(J10-F10,"") | N10: =IFERROR(J10-L10,"") | O10: =IFERROR(J10-H10,"") | P10: =IFERROR(K10-F10,"") | Y10: =IF(X10="","",IF(X10>='Léeme'!$B$6,"barato",IF(X10<'Léeme'!$B$7,"caro","medio"))) | Z10: -0.06130771 | AA10: 0.024797098
A11: 1994-T2 | B11: 34515 | C11: 13.625 | D11: 1.05 | E11: 1.12 | F11: 0.0734 | G11: 0.022884882 | H11: 0.0878 | I11: =IFERROR(C11/D11,"") | J11: =IFERROR(D11/C11,"") | K11: =IFERROR(E11/C11,"") | L11: =IFERROR(F11-G11,"") | M11: =IFERROR(J11-F11,"") | N11: =IFERROR(J11-L11,"") | O11: =IFERROR(J11-H11,"") | P11: =IFERROR(K11-F11,"") | Y11: =IF(X11="","",IF(X11>='Léeme'!$B$6,"barato",IF(X11<'Léeme'!$B$7,"caro","medio"))) | Z11: 0.03779907 | AA11: 0.058412264
A12: 1994-T3 | B12: 34607 | C12: 12.25 | D12: 1.05 | E12: 1.16 | F12: 0.0762 | G12: 0.029005525 | H12: 0.0916 | I12: =IFERROR(C12/D12,"") | J12: =IFERROR(D12/C12,"") | K12: =IFERROR(E12/C12,"") | L12: =IFERROR(F12-G12,"") | M12: =IFERROR(J12-F12,"") | N12: =IFERROR(J12-L12,"") | O12: =IFERROR(J12-H12,"") | P12: =IFERROR(K12-F12,"") | Y12: =IF(X12="","",IF(X12>='Léeme'!$B$6,"barato",IF(X12<'Léeme'!$B$7,"caro","medio"))) | Z12: 0.16664439 | AA12: 0.041344725
A13: 1994-T4 | B13: 34698 | C13: 12.25 | D13: 1.05 | E13: 1.16 | F13: 0.0784 | G13: 0.026027397 | H13: 0.091 | I13: =IFERROR(C13/D13,"") | J13: =IFERROR(D13/C13,"") | K13: =IFERROR(E13/C13,"") | L13: =IFERROR(F13-G13,"") | M13: =IFERROR(J13-F13,"") | N13: =IFERROR(J13-L13,"") | O13: =IFERROR(J13-H13,"") | P13: =IFERROR(K13-F13,"") | U13: 0.77777778 | V13: 0.26388889 | Y13: =IF(X13="","",IF(X13>='Léeme'!$B$6,"barato",IF(X13<'Léeme'!$B$7,"caro","medio"))) | Z13: 0.12075844 | AA13: 0.030659075
A14: 1995-T1 | B14: 34789 | C14: 12.125 | D14: 1.16 | E14: 1.16 | F14: 0.072 | G14: 0.028629857 | H14: 0.0866 | I14: =IFERROR(C14/D14,"") | J14: =IFERROR(D14/C14,"") | K14: =IFERROR(E14/C14,"") | L14: =IFERROR(F14-G14,"") | M14: =IFERROR(J14-F14,"") | N14: =IFERROR(J14-L14,"") | O14: =IFERROR(J14-H14,"") | P14: =IFERROR(K14-F14,"") | U14: 0.78205128 | V14: 0.57692308 | Y14: =IF(X14="","",IF(X14>='Léeme'!$B$6,"barato",IF(X14<'Léeme'!$B$7,"caro","medio"))) | Z14: 0.17520029 | AA14: 0.041351422
A15: 1995-T2 | B15: 34880 | C15: 13.125 | D15: 1.16 | E15: 1.16 | F15: 0.0621 | G15: 0.031186441 | H15: 0.0799 | I15: =IFERROR(C15/D15,"") | J15: =IFERROR(D15/C15,"") | K15: =IFERROR(E15/C15,"") | L15: =IFERROR(F15-G15,"") | M15: =IFERROR(J15-F15,"") | N15: =IFERROR(J15-L15,"") | O15: =IFERROR(J15-H15,"") | P15: =IFERROR(K15-F15,"") | U15: 0.44047619 | V15: 0.70238095 | Y15: =IF(X15="","",IF(X15>='Léeme'!$B$6,"barato",IF(X15<'Léeme'!$B$7,"caro","medio"))) | Z15: 0.1352454 | AA15: 0.027244433
A16: 1995-T3 | B16: 34971 | C16: 13.25 | D16: 1.16 | E16: 1.16 | F16: 0.0617 | G16: 0.026174497 | H16: 0.0795 | I16: =IFERROR(C16/D16,"") | J16: =IFERROR(D16/C16,"") | K16: =IFERROR(E16/C16,"") | L16: =IFERROR(F16-G16,"") | M16: =IFERROR(J16-F16,"") | N16: =IFERROR(J16-L16,"") | O16: =IFERROR(J16-H16,"") | P16: =IFERROR(K16-F16,"") | U16: 0.41111111 | V16: 0.61111111 | Y16: =IF(X16="","",IF(X16>='Léeme'!$B$6,"barato",IF(X16<'Léeme'!$B$7,"caro","medio"))) | Z16: 0.10344785 | AA16: 0.023564574
A17: 1995-T4 | B17: 35062 | C17: 12.75 | D17: 1.16 | E17: 1.16 | F17: 0.0558 | G17: 0.026034713 | H17: 0.0741 | I17: =IFERROR(C17/D17,"") | J17: =IFERROR(D17/C17,"") | K17: =IFERROR(E17/C17,"") | L17: =IFERROR(F17-G17,"") | M17: =IFERROR(J17-F17,"") | N17: =IFERROR(J17-L17,"") | O17: =IFERROR(J17-H17,"") | P17: =IFERROR(K17-F17,"") | U17: 0.57291667 | V17: 0.86458333 | Y17: =IF(X17="","",IF(X17>='Léeme'!$B$6,"barato",IF(X17<'Léeme'!$B$7,"caro","medio"))) | Z17: 0.31474716 | AA17: 0.029101653
A18: 1996-T1 | B18: 35153 | C18: 13.25 | D18: 1.24 | E18: 1.16 | F18: 0.0634 | G18: 0.027170311 | H18: 0.0817 | I18: =IFERROR(C18/D18,"") | J18: =IFERROR(D18/C18,"") | K18: =IFERROR(E18/C18,"") | L18: =IFERROR(F18-G18,"") | M18: =IFERROR(J18-F18,"") | N18: =IFERROR(J18-L18,"") | O18: =IFERROR(J18-H18,"") | P18: =IFERROR(K18-F18,"") | Q18: 0.90540541 | R18: 0.87837838 | S18: 0.7972973 | T18: 0.90540541 | U18: 0.37254902 | V18: 0.48039216 | X18: 0.72323794 | Y18: =IF(X18="","",IF(X18>='Léeme'!$B$6,"barato",IF(X18<'Léeme'!$B$7,"caro","medio"))) | Z18: 0.2012613 | AA18: 0.046060128
A19: 1996-T2 | B19: 35244 | C19: 13.875 | D19: 1.24 | E19: 1.16 | F19: 0.0673 | G19: 0.028270874 | H19: 0.0834 | I19: =IFERROR(C19/D19,"") | J19: =IFERROR(D19/C19,"") | K19: =IFERROR(E19/C19,"") | L19: =IFERROR(F19-G19,"") | M19: =IFERROR(J19-F19,"") | N19: =IFERROR(J19-L19,"") | O19: =IFERROR(J19-H19,"") | P19: =IFERROR(K19-F19,"") | Q19: 0.7125 | R19: 0.3625 | S19: 0.3375 | T19: 0.4375 | U19: 0.30555556 | V19: 0.19444444 | X19: 0.39166667 | Y19: =IF(X19="","",IF(X19>='Léeme'!$B$6,"barato",IF(X19<'Léeme'!$B$7,"caro","medio"))) | Z19: 0.17925981 | AA19: 0.072730985
A20: 1996-T3 | B20: 35338 | C20: 13.625 | D20: 1.24 | E20: 1.2 | F20: 0.0672 | G20: 0.028122956 | H20: 0.0821 | I20: =IFERROR(C20/D20,"") | J20: =IFERROR(D20/C20,"") | K20: =IFERROR(E20/C20,"") | L20: =IFERROR(F20-G20,"") | M20: =IFERROR(J20-F20,"") | N20: =IFERROR(J20-L20,"") | O20: =IFERROR(J20-H20,"") | P20: =IFERROR(K20-F20,"") | Q20: 0.8372093 | R20: 0.47674419 | S20: 0.40697674 | T20: 0.6627907 | U20: 0.42105263 | V20: 0.34210526 | X20: 0.5244798 | Y20: =IF(X20="","",IF(X20>='Léeme'!$B$6,"barato",IF(X20<'Léeme'!$B$7,"caro","medio"))) | Z20: 0.24760839 | AA20: 0.071915604
A21: 1996-T4 | B21: 35430 | C21: 15.875 | D21: 1.24 | E21: 1.2 | F21: 0.0643 | G21: 0.032530904 | H21: 0.0786 | I21: =IFERROR(C21/D21,"") | J21: =IFERROR(D21/C21,"") | K21: =IFERROR(E21/C21,"") | L21: =IFERROR(F21-G21,"") | M21: =IFERROR(J21-F21,"") | N21: =IFERROR(J21-L21,"") | O21: =IFERROR(J21-H21,"") | P21: =IFERROR(K21-F21,"") | Q21: 0.14130435 | R21: 0.27173913 | S21: 0.29347826 | T21: 0.27173913 | U21: 0.0083333333 | V21: 0.075 | X21: 0.17693237 | Y21: =IF(X21="","",IF(X21>='Léeme'!$B$6,"barato",IF(X21<'Léeme'!$B$7,"caro","medio"))) | Z21: 0.19773252 | AA21: 0.036030973
A22: 1997-T1 | B22: 35520 | C22: 14.75 | D22: 1.34 | E22: 1.2 | F22: 0.0692 | G22: 0.030322581 | H22: 0.0832 | I22: =IFERROR(C22/D22,"") | J22: =IFERROR(D22/C22,"") | K22: =IFERROR(E22/C22,"") | L22: =IFERROR(F22-G22,"") | M22: =IFERROR(J22-F22,"") | N22: =IFERROR(J22-L22,"") | O22: =IFERROR(J22-H22,"") | P22: =IFERROR(K22-F22,"") | Q22: 0.76530612 | R22: 0.37755102 | S22: 0.43877551 | T22: 0.58163265 | U22: 0.24603175 | V22: 0.11904762 | X22: 0.42139078 | Y22: =IF(X22="","",IF(X22>='Léeme'!$B$6,"barato",IF(X22<'Léeme'!$B$7,"caro","medio"))) | Z22: 0.26899568 | AA22: 0.067238807
A23: 1997-T2 | B23: 35611 | C23: 15.3125 | D23: 1.34 | E23: 1.2 | F23: 0.0651 | G23: 0.022378517 | H23: 0.0797 | I23: =IFERROR(C23/D23,"") | J23: =IFERROR(D23/C23,"") | K23: =IFERROR(E23/C23,"") | L23: =IFERROR(F23-G23,"") | M23: =IFERROR(J23-F23,"") | N23: =IFERROR(J23-L23,"") | O23: =IFERROR(J23-H23,"") | P23: =IFERROR(K23-F23,"") | Q23: 0.52884615 | R23: 0.39423077 | S23: 0.24038462 | T23: 0.58653846 | U23: 0.098484848 | V23: 0.15909091 | X23: 0.33459596 | Y23: =IF(X23="","",IF(X23>='Léeme'!$B$6,"barato",IF(X23<'Léeme'!$B$7,"caro","medio"))) | Z23: 0.12143783 | AA23: 0.088767547
A24: 1997-T3 | B24: 35703 | C24: 15.9375 | D24: 1.34 | E24: 1.2 | F24: 0.0612 | G24: 0.022900763 | H24: 0.0764 | I24: =IFERROR(C24/D24,"") | J24: =IFERROR(D24/C24,"") | K24: =IFERROR(E24/C24,"") | L24: =IFERROR(F24-G24,"") | M24: =IFERROR(J24-F24,"") | N24: =IFERROR(J24-L24,"") | O24: =IFERROR(J24-H24,"") | P24: =IFERROR(K24-F24,"") | Q24: 0.3 | R24: 0.44545455 | S24: 0.28181818 | T24: 0.57272727 | U24: 0.0072463768 | V24: 0.19565217 | X24: 0.30048309 | Y24: =IF(X24="","",IF(X24>='Léeme'!$B$6,"barato",IF(X24<'Léeme'!$B$7,"caro","medio"))) | Z24: -0.026473938 | AA24: 0.08174101
A25: 1997-T4 | B25: 35795 | C25: 17.875 | D25: 1.34 | E25: 1.2 | F25: 0.0575 | G25: 0.018903592 | H25: 0.0732 | I25: =IFERROR(C25/D25,"") | J25: =IFERROR(D25/C25,"") | K25: =IFERROR(E25/C25,"") | L25: =IFERROR(F25-G25,"") | M25: =IFERROR(J25-F25,"") | N25: =IFERROR(J25-L25,"") | O25: =IFERROR(J25-H25,"") | P25: =IFERROR(K25-F25,"") | Q25: 0.0086206897 | R25: 0.25 | S25: 0.14655172 | T25: 0.28448276 | U25: 0.0069444444 | V25: 0.034722222 | X25: 0.12188697 | Y25: =IF(X25="","",IF(X25>='Léeme'!$B$6,"barato",IF(X25<'Léeme'!$B$7,"caro","medio"))) | Z25: -0.21205241 | AA25: 0.046926151
A26: 1998-T1 | B26: 35885 | C26: 17.625 | D26: 1.4132 | E26: 1.2 | F26: 0.0567 | G26: 0.014402004 | H26: 0.0736 | I26: =IFERROR(C26/D26,"") | J26: =IFERROR(D26/C26,"") | K26: =IFERROR(E26/C26,"") | L26: =IFERROR(F26-G26,"") | M26: =IFERROR(J26-F26,"") | N26: =IFERROR(J26-L26,"") | O26: =IFERROR(J26-H26,"") | P26: =IFERROR(K26-F26,"") | Q26: 0.20491803 | R26: 0.48360656 | S26: 0.18852459 | T26: 0.46721311 | U26: 0.02 | V26: 0.11333333 | X26: 0.24626594 | Y26: =IF(X26="","",IF(X26>='Léeme'!$B$6,"barato",IF(X26<'Léeme'!$B$7,"caro","medio"))) | Z26: -0.3221687 | AA26: 0.047434545
A27: 1998-T2 | B27: 35976 | C27: 16.1875 | D27: 1.4132 | E27: 1.24 | F27: 0.0544 | G27: 0.016885553 | H27: 0.0713 | I27: =IFERROR(C27/D27,"") | J27: =IFERROR(D27/C27,"") | K27: =IFERROR(E27/C27,"") | L27: =IFERROR(F27-G27,"") | M27: =IFERROR(J27-F27,"") | N27: =IFERROR(J27-L27,"") | O27: =IFERROR(J27-H27,"") | P27: =IFERROR(K27-F27,"") | Q27: 0.5859375 | R27: 0.9609375 | S27: 0.4609375 | T27: 0.9765625 | U27: 0.16025641 | V27: 0.54487179 | X27: 0.6149172 | Y27: =IF(X27="","",IF(X27>='Léeme'!$B$6,"barato",IF(X27<'Léeme'!$B$7,"caro","medio"))) | Z27: -0.14751531 | AA27: 0.094149757
A28: 1998-T3 | B28: 36068 | C28: 14.625 | D28: 1.4132 | E28: 1.24 | F28: 0.0444 | G28: 0.016169154 | H28: 0.0709 | I28: =IFERROR(C28/D28,"") | J28: =IFERROR(D28/C28,"") | K28: =IFERROR(E28/C28,"") | L28: =IFERROR(F28-G28,"") | M28: =IFERROR(J28-F28,"") | N28: =IFERROR(J28-L28,"") | O28: =IFERROR(J28-H28,"") | P28: =IFERROR(K28-F28,"") | Q28: 0.97761194 | R28: 0.97761194 | S28: 0.97761194 | T28: 0.97761194 | U28: 0.5 | V28: 0.95679012 | X28: 0.89453965 | Y28: =IF(X28="","",IF(X28>='Léeme'!$B$6,"barato",IF(X28<'Léeme'!$B$7,"caro","medio"))) | Z28: -0.2168293 | AA28: 0.11355179
A29: 1998-T4 | B29: 36160 | C29: 13.25 | D29: 1.4132 | E29: 1.24 | F29: 0.0465 | G29: 0.014842301 | H29: 0.0726 | I29: =IFERROR(C29/D29,"") | J29: =IFERROR(D29/C29,"") | K29: =IFERROR(E29/C29,"") | L29: =IFERROR(F29-G29,"") | M29: =IFERROR(J29-F29,"") | N29: =IFERROR(J29-L29,"") | O29: =IFERROR(J29-H29,"") | P29: =IFERROR(K29-F29,"") | Q29: 0.97857143 | R29: 0.99285714 | S29: 0.99285714 | T29: 0.97857143 | U29: 0.7797619 | V29: 0.99404762 | X29: 0.95277778 | Y29: =IF(X29="","",IF(X29>='Léeme'!$B$6,"barato",IF(X29<'Léeme'!$B$7,"caro","medio"))) | Z29: -0.18709225 | AA29: 0.14536496
A30: 1999-T1 | B30: 36250 | C30: 11.1875 | D30: 1.4463 | E30: 1.24 | F30: 0.0525 | G30: 0.016666667 | H30: 0.0753 | I30: =IFERROR(C30/D30,"") | J30: =IFERROR(D30/C30,"") | K30: =IFERROR(E30/C30,"") | L30: =IFERROR(F30-G30,"") | M30: =IFERROR(J30-F30,"") | N30: =IFERROR(J30-L30,"") | O30: =IFERROR(J30-H30,"") | P30: =IFERROR(K30-F30,"") | Q30: 0.99315068 | R30: 0.99315068 | S30: 0.99315068 | T30: 0.99315068 | U30: 0.97126437 | V30: 0.99425287 | W30: 0.98648649 | X30: 0.9892295 | Y30: =IF(X30="","",IF(X30>='Léeme'!$B$6,"barato",IF(X30<'Léeme'!$B$7,"caro","medio"))) | Z30: 0.016998679 | AA30: 0.20871012
A31: 1999-T2 | B31: 36341 | C31: 12.875 | D31: 1.4463 | E31: 1.24 | F31: 0.0581 | G31: 0.020910209 | H31: 0.0805 | I31: =IFERROR(C31/D31,"") | J31: =IFERROR(D31/C31,"") | K31: =IFERROR(E31/C31,"") | L31: =IFERROR(F31-G31,"") | M31: =IFERROR(J31-F31,"") | N31: =IFERROR(J31-L31,"") | O31: =IFERROR(J31-H31,"") | P31: =IFERROR(K31-F31,"") | Q31: 0.95394737 | R31: 0.91447368 | S31: 0.92763158 | T31: 0.91447368 | U31: 0.87222222 | V31: 0.88333333 | W31: 0.9125 | X31: 0.91122598 | Y31: =IF(X31="","",IF(X31>='Léeme'!$B$6,"barato",IF(X31<'Léeme'!$B$7,"caro","medio"))) | Z31: -0.1062667 | AA31: 0.14233802
A32: 1999-T3 | B32: 36433 | C32: 10.625 | D32: 1.4463 | E32: 1.24 | F32: 0.059 | G32: 0.022643819 | H32: 0.0828 | I32: =IFERROR(C32/D32,"") | J32: =IFERROR(D32/C32,"") | K32: =IFERROR(E32/C32,"") | L32: =IFERROR(F32-G32,"") | M32: =IFERROR(J32-F32,"") | N32: =IFERROR(J32-L32,"") | O32: =IFERROR(J32-H32,"") | P32: =IFERROR(K32-F32,"") | Q32: 0.99367089 | R32: 0.99367089 | S32: 0.99367089 | T32: 0.98101266 | U32: 0.99462366 | V32: 0.98387097 | W32: 0.98837209 | X32: 0.98984172 | Y32: =IF(X32="","",IF(X32>='Léeme'!$B$6,"barato",IF(X32<'Léeme'!$B$7,"caro","medio"))) | Z32: 0.070390192 | AA32: 0.19932855
A33: 1999-T4 | B33: 36525 | C33: 9.9375 | D33: 1.4463 | E33: 1.24 | F33: 0.0645 | G33: 0.026203534 | H33: 0.0823 | I33: =IFERROR(C33/D33,"") | J33: =IFERROR(D33/C33,"") | K33: =IFERROR(E33/C33,"") | L33: =IFERROR(F33-G33,"") | M33: =IFERROR(J33-F33,"") | N33: =IFERROR(J33-L33,"") | O33: =IFERROR(J33-H33,"") | P33: =IFERROR(K33-F33,"") | Q33: 0.99390244 | R33: 0.99390244 | S33: 0.99390244 | T33: 0.99390244 | U33: 0.99479167 | V33: 0.99479167 | W33: 0.98913043 | X33: 0.99347479 | Y33: =IF(X33="","",IF(X33>='Léeme'!$B$6,"barato",IF(X33<'Léeme'!$B$7,"caro","medio"))) | Z33: 0.12630754 | AA33: 0.2434767
A34: 2000-T1 | B34: 36616 | C34: 10.4375 | D34: 1.5142 | E34: 1.24 | F34: 0.0603 | G34: 0.032179721 | H34: 0.0836 | I34: =IFERROR(C34/D34,"") | J34: =IFERROR(D34/C34,"") | K34: =IFERROR(E34/C34,"") | L34: =IFERROR(F34-G34,"") | M34: =IFERROR(J34-F34,"") | N34: =IFERROR(J34-L34,"") | O34: =IFERROR(J34-H34,"") | P34: =IFERROR(K34-F34,"") | Q34: 0.98235294 | R34: 0.99411765 | S34: 0.99411765 | T34: 0.98235294 | U34: 0.96464646 | V34: 0.98484848 | W34: 0.96938776 | X34: 0.98168913 | Y34: =IF(X34="","",IF(X34>='Léeme'!$B$6,"barato",IF(X34<'Léeme'!$B$7,"caro","medio"))) | Z34: 0.23875404 | AA34: 0.20207815
A35: 2000-T2 | B35: 36707 | C35: 10.515625 | D35: 1.5142 | E35: 1.24 | F35: 0.0603 | G35: 0.031325301 | H35: 0.0844 | I35: =IFERROR(C35/D35,"") | J35: =IFERROR(D35/C35,"") | K35: =IFERROR(E35/C35,"") | L35: =IFERROR(F35-G35,"") | M35: =IFERROR(J35-F35,"") | N35: =IFERROR(J35-L35,"") | O35: =IFERROR(J35-H35,"") | P35: =IFERROR(K35-F35,"") | Q35: 0.97159091 | R35: 0.98295455 | S35: 0.98295455 | T35: 0.97159091 | U35: 0.95588235 | V35: 0.95588235 | W35: 0.95192308 | X35: 0.96753981 | Y35: =IF(X35="","",IF(X35>='Léeme'!$B$6,"barato",IF(X35<'Léeme'!$B$7,"caro","medio"))) | Z35: 0.48159694 | AA35: 0.22329519
A36: 2000-T3 | B36: 36798 | C36: 10.375 | D36: 1.5142 | E36: 1.24 | F36: 0.058 | G36: 0.033512867 | H36: 0.0832 | I36: =IFERROR(C36/D36,"") | J36: =IFERROR(D36/C36,"") | K36: =IFERROR(E36/C36,"") | L36: =IFERROR(F36-G36,"") | M36: =IFERROR(J36-F36,"") | N36: =IFERROR(J36-L36,"") | O36: =IFERROR(J36-H36,"") | P36: =IFERROR(K36-F36,"") | Q36: 0.99450549 | R36: 0.99450549 | S36: 0.98351648 | T36: 0.98351648 | U36: 0.96666667 | V36: 0.9952381 | W36: 0.97272727 | X36: 0.98438228 | Y36: =IF(X36="","",IF(X36>='Léeme'!$B$6,"barato",IF(X36<'Léeme'!$B$7,"caro","medio"))) | Z36: 0.38988397 | AA36: 0.2182835
A37: 2000-T4 | B37: 36889 | C37: 10.1875 | D37: 1.5142 | E37: 1.26 | F37: 0.0512 | G37: 0.034441805 | H37: 0.0796 | I37: =IFERROR(C37/D37,"") | J37: =IFERROR(D37/C37,"") | K37: =IFERROR(E37/C37,"") | L37: =IFERROR(F37-G37,"") | M37: =IFERROR(J37-F37,"") | N37: =IFERROR(J37-L37,"") | O37: =IFERROR(J37-H37,"") | P37: =IFERROR(K37-F37,"") | Q37: 0.97340426 | R37: 0.99468085 | S37: 0.99468085 | T37: 0.98404255 | U37: 0.96759259 | V37: 0.99537037 | W37: 0.92241379 | X37: 0.97602647 | Y37: =IF(X37="","",IF(X37>='Léeme'!$B$6,"barato",IF(X37<'Léeme'!$B$7,"caro","medio"))) | Z37: 0.38880254 | AA37: 0.22741198
A38: 2001-T1 | B38: 36980 | C38: 11.8 | D38: 1.4453 | E38: 1.26 | F38: 0.0493 | G38: 0.035294118 | H38: 0.08 | I38: =IFERROR(C38/D38,"") | J38: =IFERROR(D38/C38,"") | K38: =IFERROR(E38/C38,"") | L38: =IFERROR(F38-G38,"") | M38: =IFERROR(J38-F38,"") | N38: =IFERROR(J38-L38,"") | O38: =IFERROR(J38-H38,"") | P38: =IFERROR(K38-F38,"") | Q38: 0.77835052 | R38: 0.81958763 | S38: 0.8814433 | T38: 0.79896907 | U38: 0.75225225 | V38: 0.87837838 | W38: 0.6147541 | X38: 0.78910503 | Y38: =IF(X38="","",IF(X38>='Léeme'!$B$6,"barato",IF(X38<'Léeme'!$B$7,"caro","medio"))) | Z38: 0.27767622 | AA38: 0.21731845
A39: 2001-T2 | B39: 37071 | C39: 14.25 | D39: 1.4453 | E39: 1.26 | F39: 0.0542 | G39: 0.035630841 | H39: 0.0801 | I39: =IFERROR(C39/D39,"") | J39: =IFERROR(D39/C39,"") | K39: =IFERROR(E39/C39,"") | L39: =IFERROR(F39-G39,"") | M39: =IFERROR(J39-F39,"") | N39: =IFERROR(J39-L39,"") | O39: =IFERROR(J39-H39,"") | P39: =IFERROR(K39-F39,"") | Q39: 0.685 | R39: 0.655 | S39: 0.755 | T39: 0.655 | U39: 0.46052632 | V39: 0.63596491 | W39: 0.1015625 | X39: 0.56400768 | Y39: =IF(X39="","",IF(X39>='Léeme'!$B$6,"barato",IF(X39<'Léeme'!$B$7,"caro","medio"))) | Z39: 0.20858176 | AA39: 0.13565686
A40: 2001-T3 | B40: 37162 | C40: 13.25 | D40: 1.4453 | E40: 1.26 | F40: 0.046 | G40: 0.027214823 | H40: 0.0805 | I40: =IFERROR(C40/D40,"") | J40: =IFERROR(D40/C40,"") | K40: =IFERROR(E40/C40,"") | L40: =IFERROR(F40-G40,"") | M40: =IFERROR(J40-F40,"") | N40: =IFERROR(J40-L40,"") | O40: =IFERROR(J40-H40,"") | P40: =IFERROR(K40-F40,"") | Q40: 0.71359223 | R40: 0.77184466 | S40: 0.7815534 | T40: 0.68446602 | U40: 0.67094017 | V40: 0.83333333 | W40: 0.24626866 | X40: 0.67171407 | Y40: =IF(X40="","",IF(X40>='Léeme'!$B$6,"barato",IF(X40<'Léeme'!$B$7,"caro","medio"))) | Z40: 0.31232612 | AA40: 0.17145708
...

Sheet O
A1: Trimestre | B1: Fecha | C1: Precio | D1: Flujo por acción, 12 meses | E1: Dividendo anualizado | F1: Treasury 10 años | G1: Inflación 12 meses | H1: Bonos Baa | I1: Múltiplo precio/flujo | J1: Yield de flujo | K1: Yield de dividendo | L1: Tasa real | M1: Prima sobre el Treasury | N1: Prima sobre la tasa real | O1: Prima sobre bonos Baa | P1: Dividendo sobre el Treasury | Q1: Percentil: Múltiplo P/FFO | R1: Percentil: Prima sobre el Treasury | S1: Percentil: Prima sobre la tasa real | T1: Percentil: Prima sobre bonos Baa | U1: Percentil: Yield de dividendo | V1: Percentil: Dividendo sobre el Treasury | W1: Percentil: Múltiplo contra sus últimos 5 años | X1: Percentil: Consenso de los siete | Y1: Señal del consenso | Z1: Retorno anual, 1 año después | AA1: Retorno anual, 5 años después
A2: 1994-T4 | B2: 34698 | C2: 8.5625 | E2: 0.9 | F2: 0.0784 | G2: 0.026027397 | H2: 0.091 | I2: =IFERROR(C2/D2,"") | J2: =IFERROR(D2/C2,"") | K2: =IFERROR(E2/C2,"") | L2: =IFERROR(F2-G2,"") | M2: =IFERROR(J2-F2,"") | N2: =IFERROR(J2-L2,"") | O2: =IFERROR(J2-H2,"") | P2: =IFERROR(K2-F2,"") | Y2: =IF(X2="","",IF(X2>='Léeme'!$B$6,"barato",IF(X2<'Léeme'!$B$7,"caro","medio"))) | Z2: 0.43585758 | AA2: 0.11429622
A3: 1995-T1 | B3: 34789 | C3: 9.0625 | E3: 0.9 | F3: 0.072 | G3: 0.028629857 | H3: 0.0866 | I3: =IFERROR(C3/D3,"") | J3: =IFERROR(D3/C3,"") | K3: =IFERROR(E3/C3,"") | L3: =IFERROR(F3-G3,"") | M3: =IFERROR(J3-F3,"") | N3: =IFERROR(J3-L3,"") | O3: =IFERROR(J3-H3,"") | P3: =IFERROR(K3-F3,"") | Y3: =IF(X3="","",IF(X3>='Léeme'!$B$6,"barato",IF(X3<'Léeme'!$B$7,"caro","medio"))) | Z3: 0.24080914 | AA3: 0.084799037
A4: 1995-T2 | B4: 34880 | C4: 10.5625 | E4: 0.9 | F4: 0.0621 | G4: 0.031186441 | H4: 0.0799 | I4: =IFERROR(C4/D4,"") | J4: =IFERROR(D4/C4,"") | K4: =IFERROR(E4/C4,"") | L4: =IFERROR(F4-G4,"") | M4: =IFERROR(J4-F4,"") | N4: =IFERROR(J4-L4,"") | O4: =IFERROR(J4-H4,"") | P4: =IFERROR(K4-F4,"") | Y4: =IF(X4="","",IF(X4>='Léeme'!$B$6,"barato",IF(X4<'Léeme'!$B$7,"caro","medio"))) | Z4: 0.064448 | AA4: 0.095746681
A5: 1995-T3 | B5: 34971 | C5: 10.5625 | E5: 0.93 | F5: 0.0617 | G5: 0.026174497 | H5: 0.0795 | I5: =IFERROR(C5/D5,"") | J5: =IFERROR(D5/C5,"") | K5: =IFERROR(E5/C5,"") | L5: =IFERROR(F5-G5,"") | M5: =IFERROR(J5-F5,"") | N5: =IFERROR(J5-L5,"") | O5: =IFERROR(J5-H5,"") | P5: =IFERROR(K5-F5,"") | Y5: =IF(X5="","",IF(X5>='Léeme'!$B$6,"barato",IF(X5<'Léeme'!$B$7,"caro","medio"))) | Z5: 0.16618186 | AA5: 0.09354619
A6: 1995-T4 | B6: 35062 | C6: 11.25 | E6: 0.93 | F6: 0.0558 | G6: 0.026034713 | H6: 0.0741 | I6: =IFERROR(C6/D6,"") | J6: =IFERROR(D6/C6,"") | K6: =IFERROR(E6/C6,"") | L6: =IFERROR(F6-G6,"") | M6: =IFERROR(J6-F6,"") | N6: =IFERROR(J6-L6,"") | O6: =IFERROR(J6-H6,"") | P6: =IFERROR(K6-F6,"") | Y6: =IF(X6="","",IF(X6>='Léeme'!$B$6,"barato",IF(X6<'Léeme'!$B$7,"caro","medio"))) | Z6: 0.12983795 | AA6: 0.090712777
A7: 1996-T1 | B7: 35153 | C7: 10.375001 | E7: 0.93 | F7: 0.0634 | G7: 0.027170311 | H7: 0.0817 | I7: =IFERROR(C7/D7,"") | J7: =IFERROR(D7/C7,"") | K7: =IFERROR(E7/C7,"") | L7: =IFERROR(F7-G7,"") | M7: =IFERROR(J7-F7,"") | N7: =IFERROR(J7-L7,"") | O7: =IFERROR(J7-H7,"") | P7: =IFERROR(K7-F7,"") | Y7: =IF(X7="","",IF(X7>='Léeme'!$B$6,"barato",IF(X7<'Léeme'!$B$7,"caro","medio"))) | Z7: 0.21656993 | AA7: 0.12080155
A8: 1996-T2 | B8: 35244 | C8: 10.375001 | E8: 0.93 | F8: 0.0673 | G8: 0.028270874 | H8: 0.0834 | I8: =IFERROR(C8/D8,"") | J8: =IFERROR(D8/C8,"") | K8: =IFERROR(E8/C8,"") | L8: =IFERROR(F8-G8,"") | M8: =IFERROR(J8-F8,"") | N8: =IFERROR(J8-L8,"") | O8: =IFERROR(J8-H8,"") | P8: =IFERROR(K8-F8,"") | Y8: =IF(X8="","",IF(X8>='Léeme'!$B$6,"barato",IF(X8<'Léeme'!$B$7,"caro","medio"))) | Z8: 0.34750043 | AA8: 0.13985667
A9: 1996-T3 | B9: 35338 | C9: 11.375001 | E9: 0.93 | F9: 0.0672 | G9: 0.028122956 | H9: 0.0821 | I9: =IFERROR(C9/D9,"") | J9: =IFERROR(D9/C9,"") | K9: =IFERROR(E9/C9,"") | L9: =IFERROR(F9-G9,"") | M9: =IFERROR(J9-F9,"") | N9: =IFERROR(J9-L9,"") | O9: =IFERROR(J9-H9,"") | P9: =IFERROR(K9-F9,"") | Y9: =IF(X9="","",IF(X9>='Léeme'!$B$6,"barato",IF(X9<'Léeme'!$B$7,"caro","medio"))) | Z9: 0.25794276 | AA9: 0.12270724
A10: 1996-T4 | B10: 35430 | C10: 11.9375 | E10: 0.945 | F10: 0.0643 | G10: 0.032530904 | H10: 0.0786 | I10: =IFERROR(C10/D10,"") | J10: =IFERROR(D10/C10,"") | K10: =IFERROR(E10/C10,"") | L10: =IFERROR(F10-G10,"") | M10: =IFERROR(J10-F10,"") | N10: =IFERROR(J10-L10,"") | O10: =IFERROR(J10-H10,"") | P10: =IFERROR(K10-F10,"") | Y10: =IF(X10="","",IF(X10>='Léeme'!$B$6,"barato",IF(X10<'Léeme'!$B$7,"caro","medio"))) | Z10: 0.1305234 | AA10: 0.11488464
A11: 1997-T1 | B11: 35520 | C11: 11.5 | D11: 1.0385 | E11: 0.948 | F11: 0.0692 | G11: 0.030322581 | H11: 0.0832 | I11: =IFERROR(C11/D11,"") | J11: =IFERROR(D11/C11,"") | K11: =IFERROR(E11/C11,"") | L11: =IFERROR(F11-G11,"") | M11: =IFERROR(J11-F11,"") | N11: =IFERROR(J11-L11,"") | O11: =IFERROR(J11-H11,"") | P11: =IFERROR(K11-F11,"") | Y11: =IF(X11="","",IF(X11>='Léeme'!$B$6,"barato",IF(X11<'Léeme'!$B$7,"caro","medio"))) | Z11: 0.25329292 | AA11: 0.15065954
A12: 1997-T2 | B12: 35611 | C12: 13.125 | D12: 1.0385 | E12: 0.948 | F12: 0.0651 | G12: 0.022378517 | H12: 0.0797 | I12: =IFERROR(C12/D12,"") | J12: =IFERROR(D12/C12,"") | K12: =IFERROR(E12/C12,"") | L12: =IFERROR(F12-G12,"") | M12: =IFERROR(J12-F12,"") | N12: =IFERROR(J12-L12,"") | O12: =IFERROR(J12-H12,"") | P12: =IFERROR(K12-F12,"") | Y12: =IF(X12="","",IF(X12>='Léeme'!$B$6,"barato",IF(X12<'Léeme'!$B$7,"caro","medio"))) | Z12: 0.065155107 | AA12: 0.1443037
A13: 1997-T3 | B13: 35703 | C13: 13.46875 | D13: 1.0385 | E13: 0.948 | F13: 0.0612 | G13: 0.022900763 | H13: 0.0764 | I13: =IFERROR(C13/D13,"") | J13: =IFERROR(D13/C13,"") | K13: =IFERROR(E13/C13,"") | L13: =IFERROR(F13-G13,"") | M13: =IFERROR(J13-F13,"") | N13: =IFERROR(J13-L13,"") | O13: =IFERROR(J13-H13,"") | P13: =IFERROR(K13-F13,"") | U13: 0.041666667 | V13: 0.125 | Y13: =IF(X13="","",IF(X13>='Léeme'!$B$6,"barato",IF(X13<'Léeme'!$B$7,"caro","medio"))) | Z13: -0.019264569 | AA13: 0.1206507
A14: 1997-T4 | B14: 35795 | C14: 12.71875 | D14: 1.0385 | E14: 0.96 | F14: 0.0575 | G14: 0.018903592 | H14: 0.0732 | I14: =IFERROR(C14/D14,"") | J14: =IFERROR(D14/C14,"") | K14: =IFERROR(E14/C14,"") | L14: =IFERROR(F14-G14,"") | M14: =IFERROR(J14-F14,"") | N14: =IFERROR(J14-L14,"") | O14: =IFERROR(J14-H14,"") | P14: =IFERROR(K14-F14,"") | U14: 0.21794872 | V14: 0.3974359 | Y14: =IF(X14="","",IF(X14>='Léeme'!$B$6,"barato",IF(X14<'Léeme'!$B$7,"caro","medio"))) | Z14: 0.040067579 | AA14: 0.13884469
A15: 1998-T1 | B15: 35885 | C15: 13.59375 | D15: 1.11 | E15: 0.972 | F15: 0.0567 | G15: 0.014402004 | H15: 0.0736 | I15: =IFERROR(C15/D15,"") | J15: =IFERROR(D15/C15,"") | K15: =IFERROR(E15/C15,"") | L15: =IFERROR(F15-G15,"") | M15: =IFERROR(J15-F15,"") | N15: =IFERROR(J15-L15,"") | O15: =IFERROR(J15-H15,"") | P15: =IFERROR(K15-F15,"") | U15: 0.05952381 | V15: 0.32142857 | Y15: =IF(X15="","",IF(X15>='Léeme'!$B$6,"barato",IF(X15<'Léeme'!$B$7,"caro","medio"))) | Z15: -0.17529875 | AA15: 0.12834215
A16: 1998-T2 | B16: 35976 | C16: 13.1875 | D16: 1.11 | E16: 0.99 | F16: 0.0544 | G16: 0.016885553 | H16: 0.0713 | I16: =IFERROR(C16/D16,"") | J16: =IFERROR(D16/C16,"") | K16: =IFERROR(E16/C16,"") | L16: =IFERROR(F16-G16,"") | M16: =IFERROR(J16-F16,"") | N16: =IFERROR(J16-L16,"") | O16: =IFERROR(J16-H16,"") | P16: =IFERROR(K16-F16,"") | U16: 0.3 | V16: 0.56666667 | Y16: =IF(X16="","",IF(X16>='Léeme'!$B$6,"barato",IF(X16<'Léeme'!$B$7,"caro","medio"))) | Z16: -0.036230189 | AA16: 0.14907251
A17: 1998-T3 | B17: 36068 | C17: 12.4375 | D17: 1.11 | E17: 1.008 | F17: 0.0444 | G17: 0.016169154 | H17: 0.0709 | I17: =IFERROR(C17/D17,"") | J17: =IFERROR(D17/C17,"") | K17: =IFERROR(E17/C17,"") | L17: =IFERROR(F17-G17,"") | M17: =IFERROR(J17-F17,"") | N17: =IFERROR(J17-L17,"") | O17: =IFERROR(J17-H17,"") | P17: =IFERROR(K17-F17,"") | U17: 0.44791667 | V17: 0.96875 | Y17: =IF(X17="","",IF(X17>='Léeme'!$B$6,"barato",IF(X17<'Léeme'!$B$7,"caro","medio"))) | Z17: -0.0028507739 | AA17: 0.17104531
A18: 1998-T4 | B18: 36160 | C18: 12.4375 | D18: 1.11 | E18: 1.02 | F18: 0.0465 | G18: 0.014842301 | H18: 0.0726 | I18: =IFERROR(C18/D18,"") | J18: =IFERROR(D18/C18,"") | K18: =IFERROR(E18/C18,"") | L18: =IFERROR(F18-G18,"") | M18: =IFERROR(J18-F18,"") | N18: =IFERROR(J18-L18,"") | O18: =IFERROR(J18-H18,"") | P18: =IFERROR(K18-F18,"") | U18: 0.5 | V18: 0.95098039 | Y18: =IF(X18="","",IF(X18>='Léeme'!$B$6,"barato",IF(X18<'Léeme'!$B$7,"caro","medio"))) | Z18: -0.10750793 | AA18: 0.17208251
A19: 1999-T1 | B19: 36250 | C19: 10.500001 | D19: 1.18 | E19: 1.032 | F19: 0.0525 | G19: 0.016666667 | H19: 0.0753 | I19: =IFERROR(C19/D19,"") | J19: =IFERROR(D19/C19,"") | K19: =IFERROR(E19/C19,"") | L19: =IFERROR(F19-G19,"") | M19: =IFERROR(J19-F19,"") | N19: =IFERROR(J19-L19,"") | O19: =IFERROR(J19-H19,"") | P19: =IFERROR(K19-F19,"") | U19: 0.89814815 | V19: 0.99074074 | Y19: =IF(X19="","",IF(X19>='Léeme'!$B$6,"barato",IF(X19<'Léeme'!$B$7,"caro","medio"))) | Z19: -0.010993476 | AA19: 0.23766206
A20: 1999-T2 | B20: 36341 | C20: 11.875 | D20: 1.18 | E20: 1.05 | F20: 0.0581 | G20: 0.020910209 | H20: 0.0805 | I20: =IFERROR(C20/D20,"") | J20: =IFERROR(D20/C20,"") | K20: =IFERROR(E20/C20,"") | L20: =IFERROR(F20-G20,"") | M20: =IFERROR(J20-F20,"") | N20: =IFERROR(J20-L20,"") | O20: =IFERROR(J20-H20,"") | P20: =IFERROR(K20-F20,"") | U20: 0.71052632 | V20: 0.78070175 | Y20: =IF(X20="","",IF(X20>='Léeme'!$B$6,"barato",IF(X20<'Léeme'!$B$7,"caro","medio"))) | Z20: 0.07278152 | AA20: 0.19011371
A21: 1999-T3 | B21: 36433 | C21: 11.5625 | D21: 1.18 | E21: 1.068 | F21: 0.059 | G21: 0.022643819 | H21: 0.0828 | I21: =IFERROR(C21/D21,"") | J21: =IFERROR(D21/C21,"") | K21: =IFERROR(E21/C21,"") | L21: =IFERROR(F21-G21,"") | M21: =IFERROR(J21-F21,"") | N21: =IFERROR(J21-L21,"") | O21: =IFERROR(J21-H21,"") | P21: =IFERROR(K21-F21,"") | U21: 0.80833333 | V21: 0.80833333 | Y21: =IF(X21="","",IF(X21>='Léeme'!$B$6,"barato",IF(X21<'Léeme'!$B$7,"caro","medio"))) | Z21: 0.090050136 | AA21: 0.21328161
A22: 1999-T4 | B22: 36525 | C22: 10.3125 | D22: 1.18 | E22: 1.08 | F22: 0.0645 | G22: 0.026203534 | H22: 0.0823 | I22: =IFERROR(C22/D22,"") | J22: =IFERROR(D22/C22,"") | K22: =IFERROR(E22/C22,"") | L22: =IFERROR(F22-G22,"") | M22: =IFERROR(J22-F22,"") | N22: =IFERROR(J22-L22,"") | O22: =IFERROR(J22-H22,"") | P22: =IFERROR(K22-F22,"") | U22: 0.94444444 | V22: 0.96031746 | Y22: =IF(X22="","",IF(X22>='Léeme'!$B$6,"barato",IF(X22<'Léeme'!$B$7,"caro","medio"))) | Z22: 0.30193819 | AA22: 0.26820905
A23: 2000-T1 | B23: 36616 | C23: 9.624999 | D23: 1.2285 | E23: 1.086 | F23: 0.0603 | G23: 0.032179721 | H23: 0.0836 | I23: =IFERROR(C23/D23,"") | J23: =IFERROR(D23/C23,"") | K23: =IFERROR(E23/C23,"") | L23: =IFERROR(F23-G23,"") | M23: =IFERROR(J23-F23,"") | N23: =IFERROR(J23-L23,"") | O23: =IFERROR(J23-H23,"") | P23: =IFERROR(K23-F23,"") | Q23: 0.98648649 | R23: 0.98648649 | S23: 0.98648649 | T23: 0.98648649 | U23: 0.99242424 | V23: 0.99242424 | X23: 0.98846574 | Y23: =IF(X23="","",IF(X23>='Léeme'!$B$6,"barato",IF(X23<'Léeme'!$B$7,"caro","medio"))) | Z23: 0.48095683 | AA23: 0.25798271
A24: 2000-T2 | B24: 36707 | C24: 11.789062 | D24: 1.2285 | E24: 1.098 | F24: 0.0603 | G24: 0.031325301 | H24: 0.0844 | I24: =IFERROR(C24/D24,"") | J24: =IFERROR(D24/C24,"") | K24: =IFERROR(E24/C24,"") | L24: =IFERROR(F24-G24,"") | M24: =IFERROR(J24-F24,"") | N24: =IFERROR(J24-L24,"") | O24: =IFERROR(J24-H24,"") | P24: =IFERROR(K24-F24,"") | Q24: 0.7875 | R24: 0.6875 | S24: 0.8625 | T24: 0.6375 | U24: 0.73188406 | V24: 0.7173913 | X24: 0.73737923 | Y24: =IF(X24="","",IF(X24>='Léeme'!$B$6,"barato",IF(X24<'Léeme'!$B$7,"caro","medio"))) | Z24: 0.34488267 | AA24: 0.2279858
A25: 2000-T3 | B25: 36798 | C25: 11.65625 | D25: 1.2285 | E25: 1.104 | F25: 0.058 | G25: 0.033512867 | H25: 0.0832 | I25: =IFERROR(C25/D25,"") | J25: =IFERROR(D25/C25,"") | K25: =IFERROR(E25/C25,"") | L25: =IFERROR(F25-G25,"") | M25: =IFERROR(J25-F25,"") | N25: =IFERROR(J25-L25,"") | O25: =IFERROR(J25-H25,"") | P25: =IFERROR(K25-F25,"") | Q25: 0.80232558 | R25: 0.8255814 | S25: 0.91860465 | T25: 0.73255814 | U25: 0.74305556 | V25: 0.86805556 | X25: 0.81503015 | Y25: =IF(X25="","",IF(X25>='Léeme'!$B$6,"barato",IF(X25<'Léeme'!$B$7,"caro","medio"))) | Z25: 0.33018866 | AA25: 0.21568055
A26: 2000-T4 | B26: 36889 | C26: 12.4375 | D26: 1.2285 | E26: 1.11 | F26: 0.0512 | G26: 0.034441805 | H26: 0.0796 | I26: =IFERROR(C26/D26,"") | J26: =IFERROR(D26/C26,"") | K26: =IFERROR(E26/C26,"") | L26: =IFERROR(F26-G26,"") | M26: =IFERROR(J26-F26,"") | N26: =IFERROR(J26-L26,"") | O26: =IFERROR(J26-H26,"") | P26: =IFERROR(K26-F26,"") | Q26: 0.55434783 | R26: 0.79347826 | S26: 0.88043478 | T26: 0.55434783 | U26: 0.59333333 | V26: 0.88666667 | X26: 0.71043478 | Y26: =IF(X26="","",IF(X26>='Léeme'!$B$6,"barato",IF(X26<'Léeme'!$B$7,"caro","medio"))) | Z26: 0.27485672 | AA26: 0.17861412
A27: 2001-T1 | B27: 36980 | C27: 13.249999 | D27: 1.2285 | E27: 1.116 | F27: 0.0493 | G27: 0.035294118 | H27: 0.08 | I27: =IFERROR(C27/D27,"") | J27: =IFERROR(D27/C27,"") | K27: =IFERROR(E27/C27,"") | L27: =IFERROR(F27-G27,"") | M27: =IFERROR(J27-F27,"") | N27: =IFERROR(J27-L27,"") | O27: =IFERROR(J27-H27,"") | P27: =IFERROR(K27-F27,"") | Q27: 0.43877551 | R27: 0.58163265 | S27: 0.82653061 | T27: 0.31632653 | U27: 0.41666667 | V27: 0.77564103 | X27: 0.55926217 | Y27: =IF(X27="","",IF(X27>='Léeme'!$B$6,"barato",IF(X27<'Léeme'!$B$7,"caro","medio"))) | Z27: 0.332427 | AA27: 0.18522449
A28: 2001-T2 | B28: 37071 | C28: 14.779999 | D28: 1.2585 | E28: 1.128 | F28: 0.0542 | G28: 0.035630841 | H28: 0.0801 | I28: =IFERROR(C28/D28,"") | J28: =IFERROR(D28/C28,"") | K28: =IFERROR(E28/C28,"") | L28: =IFERROR(F28-G28,"") | M28: =IFERROR(J28-F28,"") | N28: =IFERROR(J28-L28,"") | O28: =IFERROR(J28-H28,"") | P28: =IFERROR(K28-F28,"") | Q28: 0.29807692 | R28: 0.31730769 | S28: 0.60576923 | T28: 0.14423077 | U28: 0.2037037 | V28: 0.32716049 | X28: 0.31604147 | Y28: =IF(X28="","",IF(X28>='Léeme'!$B$6,"barato",IF(X28<'Léeme'!$B$7,"caro","medio"))) | Z28: 0.32472171 | AA28: 0.14314918
A29: 2001-T3 | B29: 37162 | C29: 14.500001 | D29: 1.2585 | E29: 1.134 | F29: 0.046 | G29: 0.027214823 | H29: 0.0805 | I29: =IFERROR(C29/D29,"") | J29: =IFERROR(D29/C29,"") | K29: =IFERROR(E29/C29,"") | L29: =IFERROR(F29-G29,"") | M29: =IFERROR(J29-F29,"") | N29: =IFERROR(J29-L29,"") | O29: =IFERROR(J29-H29,"") | P29: =IFERROR(K29-F29,"") | Q29: 0.3 | R29: 0.46363636 | S29: 0.60909091 | T29: 0.19090909 | U29: 0.23214286 | V29: 0.64880952 | X29: 0.40743146 | Y29: =IF(X29="","",IF(X29>='Léeme'!$B$6,"barato",IF(X29<'Léeme'!$B$7,"caro","medio"))) | Z29: 0.24828848 | AA29: 0.16924143
A30: 2001-T4 | B30: 37256 | C30: 14.7 | D30: 1.2585 | E30: 1.14 | F30: 0.0507 | G30: 0.018943743 | H30: 0.0802 | I30: =IFERROR(C30/D30,"") | J30: =IFERROR(D30/C30,"") | K30: =IFERROR(E30/C30,"") | L30: =IFERROR(F30-G30,"") | M30: =IFERROR(J30-F30,"") | N30: =IFERROR(J30-L30,"") | O30: =IFERROR(J30-H30,"") | P30: =IFERROR(K30-F30,"") | Q30: 0.28448276 | R30: 0.31896552 | S30: 0.30172414 | T30: 0.14655172 | U30: 0.21264368 | V30: 0.45402299 | X30: 0.28639847 | Y30: =IF(X30="","",IF(X30>='Léeme'!$B$6,"barato",IF(X30<'Léeme'!$B$7,"caro","medio"))) | Z30: 0.25733902 | AA30: 0.19181306
A31: 2002-T1 | B31: 37343 | C31: 16.600001 | D31: 1.2585 | E31: 1.146 | F31: 0.0542 | G31: 0.011363636 | H31: 0.0816 | I31: =IFERROR(C31/D31,"") | J31: =IFERROR(D31/C31,"") | K31: =IFERROR(E31/C31,"") | L31: =IFERROR(F31-G31,"") | M31: =IFERROR(J31-F31,"") | N31: =IFERROR(J31-L31,"") | O31: =IFERROR(J31-H31,"") | P31: =IFERROR(K31-F31,"") | Q31: 0.024590164 | R31: 0.1557377 | S31: 0.0081967213 | T31: 0.0081967213 | U31: 0.016666667 | V31: 0.16111111 | X31: 0.062416515 | Y31: =IF(X31="","",IF(X31>='Léeme'!$B$6,"barato",IF(X31<'Léeme'!$B$7,"caro","medio"))) | Z31: 0.1366948 | AA31: 0.16246322
A32: 2002-T2 | B32: 37435 | C32: 18.459999 | D32: 1.3285 | E32: 1.158 | F32: 0.0486 | G32: 0.012408347 | H32: 0.0798 | I32: =IFERROR(C32/D32,"") | J32: =IFERROR(D32/C32,"") | K32: =IFERROR(E32/C32,"") | L32: =IFERROR(F32-G32,"") | M32: =IFERROR(J32-F32,"") | N32: =IFERROR(J32-L32,"") | O32: =IFERROR(J32-H32,"") | P32: =IFERROR(K32-F32,"") | Q32: 0.0078125 | R32: 0.1796875 | S32: 0.0390625 | T32: 0.0078125 | U32: 0.0053763441 | V32: 0.11290323 | X32: 0.058775762 | Y32: =IF(X32="","",IF(X32>='Léeme'!$B$6,"barato",IF(X32<'Léeme'!$B$7,"caro","medio"))) | Z32: 0.10667046 | AA32: 0.11750117
A33: 2002-T3 | B33: 37529 | C33: 17.075001 | D33: 1.3285 | E33: 1.158 | F33: 0.0363 | G33: 0.017474634 | H33: 0.074 | I33: =IFERROR(C33/D33,"") | J33: =IFERROR(D33/C33,"") | K33: =IFERROR(E33/C33,"") | L33: =IFERROR(F33-G33,"") | M33: =IFERROR(J33-F33,"") | N33: =IFERROR(J33-L33,"") | O33: =IFERROR(J33-H33,"") | P33: =IFERROR(K33-F33,"") | Q33: 0.082089552 | R33: 0.58955224 | S33: 0.45522388 | T33: 0.20149254 | U33: 0.026041667 | V33: 0.671875 | X33: 0.33771248 | Y33: =IF(X33="","",IF(X33>='Léeme'!$B$6,"barato",IF(X33<'Léeme'!$B$7,"caro","medio"))) | Z33: 0.22199388 | AA33: 0.15709507
A34: 2002-T4 | B34: 37621 | C34: 17.499999 | D34: 1.3285 | E34: 1.17 | F34: 0.0383 | G34: 0.022535211 | H34: 0.073 | I34: =IFERROR(C34/D34,"") | J34: =IFERROR(D34/C34,"") | K34: =IFERROR(E34/C34,"") | L34: =IFERROR(F34-G34,"") | M34: =IFERROR(J34-F34,"") | N34: =IFERROR(J34-L34,"") | O34: =IFERROR(J34-H34,"") | P34: =IFERROR(K34-F34,"") | Q34: 0.05 | R34: 0.43571429 | S34: 0.47857143 | T34: 0.19285714 | U34: 0.035353535 | V34: 0.57070707 | X34: 0.29386724 | Y34: =IF(X34="","",IF(X34>='Léeme'!$B$6,"barato",IF(X34<'Léeme'!$B$7,"caro","medio"))) | Z34: 0.20096399 | AA34: 0.14322983
A35: 2003-T1 | B35: 37711 | C35: 17.874999 | D35: 1.38 | E35: 1.176 | F35: 0.0383 | G35: 0.031460674 | H35: 0.0693 | I35: =IFERROR(C35/D35,"") | J35: =IFERROR(D35/C35,"") | K35: =IFERROR(E35/C35,"") | L35: =IFERROR(F35-G35,"") | M35: =IFERROR(J35-F35,"") | N35: =IFERROR(J35-L35,"") | O35: =IFERROR(J35-H35,"") | P35: =IFERROR(K35-F35,"") | Q35: 0.089041096 | R35: 0.44520548 | S35: 0.70547945 | T35: 0.39041096 | U35: 0.014705882 | V35: 0.5245098 | W35: 0.12162162 | X35: 0.32728204 | Y35: =IF(X35="","",IF(X35>='Léeme'!$B$6,"barato",IF(X35<'Léeme'!$B$7,"caro","medio"))) | Z35: 0.30949243 | AA35: 0.1263843
A36: 2003-T2 | B36: 37802 | C36: 19.039999 | D36: 1.38 | E36: 1.182 | F36: 0.0354 | G36: 0.018941504 | H36: 0.0638 | I36: =IFERROR(C36/D36,"") | J36: =IFERROR(D36/C36,"") | K36: =IFERROR(E36/C36,"") | L36: =IFERROR(F36-G36,"") | M36: =IFERROR(J36-F36,"") | N36: =IFERROR(J36-L36,"") | O36: =IFERROR(J36-H36,"") | P36: =IFERROR(K36-F36,"") | Q36: 0.019736842 | R36: 0.375 | S36: 0.38815789 | T36: 0.44078947 | U36: 0.0047619048 | V36: 0.45238095 | W36: 0.0375 | X36: 0.2454753 | Y36: =IF(X36="","",IF(X36>='Léeme'!$B$6,"barato",IF(X36<'Léeme'!$B$7,"caro","medio"))) | Z36: 0.14862547 | AA36: 0.086431272
